<?xml version="1.0" ?>
<!-- =================================================================================== -->
<!-- |    This document was autogenerated by xacro from panda_arm.urdf.xacro           | -->
<!-- |    EDITING THIS FILE BY HAND IS NOT RECOMMENDED                                 | -->
<!-- =================================================================================== -->
<robot name="panda">
  <link name="root">
    <inertial>
      <mass value="0"/>
      <inertia ixx="0.00" ixy="0.00" ixz="0.00" iyy="0.00" iyz="0.00" izz="0.00"/>
    </inertial>
  </link>
  <link name="root_arm_1_link_1">
    <inertial>
      <mass value="0"/>
      <inertia ixx="0.00" ixy="0.00" ixz="0.00" iyy="0.00" iyz="0.00" izz="0.00"/>
    </inertial>
  </link>
  <link name="root_arm_1_link_2">
    <inertial>
      <mass value="0"/>
      <inertia ixx="0.00" ixy="0.00" ixz="0.00" iyy="0.00" iyz="0.00" izz="0.00"/>
    </inertial>
  </link>
  <link name="root_arm_1_link_3">
    <inertial>
      <mass value="0"/>
      <inertia ixx="0.00" ixy="0.00" ixz="0.00" iyy="0.00" iyz="0.00" izz="0.00"/>
    </inertial>
  </link>
  <link name="root_arm_1_link_4">
    <inertial>
      <mass value="0"/>
      <inertia ixx="0.00" ixy="0.00" ixz="0.00" iyy="0.00" iyz="0.00" izz="0.00"/>
    </inertial>
  </link>
  <link name="root_arm_1_link_5">
    <inertial>
      <mass value="0"/>
      <inertia ixx="0.00" ixy="0.00" ixz="0.00" iyy="0.00" iyz="0.00" izz="0.00"/>
    </inertial>
  </link>
  <joint name="root_x_axis_joint" type="prismatic">
    <parent link="root"/>
    <child link="root_arm_1_link_1"/>
    <axis xyz="1 0 0"/>
    <limit effort="100" lower="-20" upper="20" velocity="0.50"/>
    <dynamics damping="10.0" friction="10"/>
  </joint>
  <joint name="root_y_axis_joint" type="prismatic">
    <parent link="root_arm_1_link_1"/>
    <child link="root_arm_1_link_2"/>
    <axis xyz="0 1 0"/>
    <limit effort="100" lower="-20" upper="20" velocity="0.50"/>
    <dynamics damping="10.0" friction="10"/>
  </joint>
  <joint name="root_z_axis_joint" type="prismatic">
    <parent link="root_arm_1_link_2"/>
    <child link="root_arm_1_link_3"/>
    <axis xyz="0 0 1"/>
    <limit effort="100" lower="-20" upper="20" velocity="0.50"/>
    <dynamics damping="10.0" friction="10"/>
  </joint>
  <joint name="root_x_rot_joint" type="revolute">
    <parent link="root_arm_1_link_3"/>
    <child link="root_arm_1_link_4"/>
    <axis xyz="1 0 0"/>
    <limit effort="100" lower="-20" upper="20" velocity="0.50"/>
    <dynamics damping="10.0" friction="10"/>
  </joint>
  <joint name="root_y_rot_joint" type="revolute">
    <parent link="root_arm_1_link_4"/>
    <child link="root_arm_1_link_5"/>
    <axis xyz="0 1 0"/>
    <limit effort="100" lower="-20" upper="20" velocity="0.50"/>
    <dynamics damping="10.0" friction="10"/>
  </joint>
  <joint name="root_z_rot_joint" type="revolute">
    <parent link="root_arm_1_link_5"/>
    <child link="panda_hand"/>
    <axis xyz="0 0 1"/>
    <limit effort="100" lower="-20" upper="20" velocity="0.50"/>
    <dynamics damping="10.0" friction="10"/>
  </joint>
  <link name="panda_hand">
    <visual>
      <geometry>
        <mesh filename="franka_description/meshes/visual/hand.glb"/>
      </geometry>
    </visual>
    <collision>
      <geometry>
        <mesh filename="franka_description/meshes/collision/hand.stl"/>
      </geometry>
    </collision>
    <inertial>
      <origin rpy="0 0 0" xyz="-0.01 0 0.03"/>
      <mass value="0.73"/>
      <inertia ixx="0.001" ixy="0" ixz="0" iyy="0.0025" iyz="0" izz="0.0017"/>
    </inertial>
  </link>
  <!-- Define the hand_tcp frame -->
  <link name="panda_hand_tcp"/>
  <joint name="panda_hand_tcp_joint" type="fixed">
    <origin rpy="0 0 0" xyz="0 0 0.1034"/>
    <parent link="panda_hand"/>
    <child link="panda_hand_tcp"/>
  </joint>
  <link name="panda_leftfinger">
    <visual>
      <origin rpy="0 0 3.14159265359" xyz="0 0 0"/>
      <geometry>
        <mesh filename="./finray/one_piece_wide_grasp_finray_finger.obj"/>
      </geometry>
    </visual>
    <collision>
      <origin rpy="0 0 3.14159265359" xyz="0 0 0"/>
      <geometry>
        <mesh filename="./finray/collider.obj"/>
      </geometry>
    </collision>
    <inertial>
      <origin rpy="0 0 0" xyz="0 0 0"/>
      <mass value="0.015"/>
      <inertia ixx="2.3749999999999997e-06" ixy="0" ixz="0" iyy="2.3749999999999997e-06" iyz="0" izz="7.5e-07"/>
    </inertial>
  </link>
  <link name="panda_rightfinger">
    <visual>
      <geometry>
        <mesh filename="./finray/one_piece_wide_grasp_finray_finger.obj"/>
      </geometry>
    </visual>
    <collision>
      <geometry>
        <mesh filename="./finray/collider.obj"/>
      </geometry>
    </collision>
    <inertial>
      <origin rpy="0 0 0" xyz="0 0 0"/>
      <mass value="0.015"/>
      <inertia ixx="2.3749999999999997e-06" ixy="0" ixz="0" iyy="2.3749999999999997e-06" iyz="0" izz="7.5e-07"/>
    </inertial>
  </link>
  <joint name="panda_finger_joint1" type="prismatic">
    <parent link="panda_hand"/>
    <child link="panda_leftfinger"/>
    <origin rpy="0 0 0" xyz="0 0 0.0584"/>
    <axis xyz="0 1 0"/>
    <limit effort="100" lower="0.0" upper="0.04" velocity="0.2"/>
    <dynamics damping="0.3"/>
  </joint>
  <joint name="panda_finger_joint2" type="prismatic">
    <parent link="panda_hand"/>
    <child link="panda_rightfinger"/>
    <origin rpy="0 0 0" xyz="0 0 0.0584"/>
    <axis xyz="0 -1 0"/>
    <limit effort="100" lower="0.0" upper="0.04" velocity="0.2"/>
    <mimic joint="panda_finger_joint1"/>
    <dynamics damping="0.3"/>
  </joint>
  <!-- Add finger pad links and joints -->
  <link name="panda_leftfinger_pad"/>
  <joint name="panda_leftfinger_pad_joint" type="fixed">
    <origin rpy="0 0 0" xyz="0 0 0.0455"/>
    <parent link="panda_leftfinger"/>
    <child link="panda_leftfinger_pad"/>
  </joint>

  <link name="panda_rightfinger_pad"/>
  <joint name="panda_rightfinger_pad_joint" type="fixed">
    <origin rpy="0 0 0" xyz="0 0 0.0455"/>
    <parent link="panda_rightfinger"/>
    <child link="panda_rightfinger_pad"/>
  </joint>
</robot>
